{"cells":[{"cell_type":"code","execution_count":1,"metadata":{"colab":{"base_uri":"https://localhost:8080/"},"executionInfo":{"elapsed":10069,"status":"ok","timestamp":1682836461383,"user":{"displayName":"Kushi Karkera","userId":"13688612516651987903"},"user_tz":-330},"id":"kPzIXScWAKbs","outputId":"147fb3b7-a6cf-4b0e-c078-ef6f6275795a"},"outputs":[{"name":"stdout","output_type":"stream","text":["Drive already mounted at /content/drive; to attempt to forcibly remount, call drive.mount(\"/content/drive\", force_remount=True).\n"]}],"source":["from google.colab import drive\n","drive.mount('/content/drive')"]},{"cell_type":"code","execution_count":2,"metadata":{"colab":{"base_uri":"https://localhost:8080/"},"executionInfo":{"elapsed":588,"status":"ok","timestamp":1682836482378,"user":{"displayName":"Kushi Karkera","userId":"13688612516651987903"},"user_tz":-330},"id":"6AdK7HTR3qnq","outputId":"6c0f0701-89f1-4492-ba97-7682ba8248d2"},"outputs":[{"name":"stdout","output_type":"stream","text":["/content/drive/MyDrive/Mini_Project\n"]}],"source":["%cd \"/content/drive/MyDrive/Mini_Project\""]},{"cell_type":"code","execution_count":3,"metadata":{"colab":{"base_uri":"https://localhost:8080/"},"executionInfo":{"elapsed":6038,"status":"ok","timestamp":1682836503881,"user":{"displayName":"Kushi Karkera","userId":"13688612516651987903"},"user_tz":-330},"id":"mNIAX_eH3xjq","outputId":"e3c392b1-50c5-4b67-98b8-7fdd5cac8f6e"},"outputs":[{"name":"stdout","output_type":"stream","text":["Looking in indexes: https://pypi.org/simple, https://us-python.pkg.dev/colab-wheels/public/simple/\n","Collecting import-ipynb\n","  Downloading import_ipynb-0.1.4-py3-none-any.whl (4.1 kB)\n","Requirement already satisfied: nbformat in /usr/local/lib/python3.10/dist-packages (from import-ipynb) (5.8.0)\n","Requirement already satisfied: IPython in /usr/local/lib/python3.10/dist-packages (from import-ipynb) (7.34.0)\n","Requirement already satisfied: setuptools\u003e=18.5 in /usr/local/lib/python3.10/dist-packages (from IPython-\u003eimport-ipynb) (67.7.2)\n","Requirement already satisfied: traitlets\u003e=4.2 in /usr/local/lib/python3.10/dist-packages (from IPython-\u003eimport-ipynb) (5.7.1)\n","Requirement already satisfied: decorator in /usr/local/lib/python3.10/dist-packages (from IPython-\u003eimport-ipynb) (4.4.2)\n","Requirement already satisfied: pickleshare in /usr/local/lib/python3.10/dist-packages (from IPython-\u003eimport-ipynb) (0.7.5)\n","Requirement already satisfied: pygments in /usr/local/lib/python3.10/dist-packages (from IPython-\u003eimport-ipynb) (2.14.0)\n","Requirement already satisfied: backcall in /usr/local/lib/python3.10/dist-packages (from IPython-\u003eimport-ipynb) (0.2.0)\n","Requirement already satisfied: prompt-toolkit!=3.0.0,!=3.0.1,\u003c3.1.0,\u003e=2.0.0 in /usr/local/lib/python3.10/dist-packages (from IPython-\u003eimport-ipynb) (3.0.38)\n","Requirement already satisfied: matplotlib-inline in /usr/local/lib/python3.10/dist-packages (from IPython-\u003eimport-ipynb) (0.1.6)\n","Requirement already satisfied: pexpect\u003e4.3 in /usr/local/lib/python3.10/dist-packages (from IPython-\u003eimport-ipynb) (4.8.0)\n","Collecting jedi\u003e=0.16\n","  Downloading jedi-0.18.2-py2.py3-none-any.whl (1.6 MB)\n","\u001b[2K     \u001b[90m━━━━━━━━━━━━━━━━━━━━━━━━━━━━━━━━━━━━━━━━\u001b[0m \u001b[32m1.6/1.6 MB\u001b[0m \u001b[31m19.0 MB/s\u001b[0m eta \u001b[36m0:00:00\u001b[0m\n","\u001b[?25hRequirement already satisfied: fastjsonschema in /usr/local/lib/python3.10/dist-packages (from nbformat-\u003eimport-ipynb) (2.16.3)\n","Requirement already satisfied: jupyter-core in /usr/local/lib/python3.10/dist-packages (from nbformat-\u003eimport-ipynb) (5.3.0)\n","Requirement already satisfied: jsonschema\u003e=2.6 in /usr/local/lib/python3.10/dist-packages (from nbformat-\u003eimport-ipynb) (4.3.3)\n","Requirement already satisfied: parso\u003c0.9.0,\u003e=0.8.0 in /usr/local/lib/python3.10/dist-packages (from jedi\u003e=0.16-\u003eIPython-\u003eimport-ipynb) (0.8.3)\n","Requirement already satisfied: pyrsistent!=0.17.0,!=0.17.1,!=0.17.2,\u003e=0.14.0 in /usr/local/lib/python3.10/dist-packages (from jsonschema\u003e=2.6-\u003enbformat-\u003eimport-ipynb) (0.19.3)\n","Requirement already satisfied: attrs\u003e=17.4.0 in /usr/local/lib/python3.10/dist-packages (from jsonschema\u003e=2.6-\u003enbformat-\u003eimport-ipynb) (23.1.0)\n","Requirement already satisfied: ptyprocess\u003e=0.5 in /usr/local/lib/python3.10/dist-packages (from pexpect\u003e4.3-\u003eIPython-\u003eimport-ipynb) (0.7.0)\n","Requirement already satisfied: wcwidth in /usr/local/lib/python3.10/dist-packages (from prompt-toolkit!=3.0.0,!=3.0.1,\u003c3.1.0,\u003e=2.0.0-\u003eIPython-\u003eimport-ipynb) (0.2.6)\n","Requirement already satisfied: platformdirs\u003e=2.5 in /usr/local/lib/python3.10/dist-packages (from jupyter-core-\u003enbformat-\u003eimport-ipynb) (3.3.0)\n","Installing collected packages: jedi, import-ipynb\n","Successfully installed import-ipynb-0.1.4 jedi-0.18.2\n"]}],"source":["!pip install import-ipynb\n","import import_ipynb"]},{"cell_type":"code","execution_count":4,"metadata":{"colab":{"base_uri":"https://localhost:8080/"},"executionInfo":{"elapsed":5441,"status":"ok","timestamp":1682836511889,"user":{"displayName":"Kushi Karkera","userId":"13688612516651987903"},"user_tz":-330},"id":"9sTroo3Sq54t","outputId":"05ee8d1d-e886-4222-d7d4-aac5855dc79b"},"outputs":[{"name":"stdout","output_type":"stream","text":["importing Jupyter notebook from image_segment.ipynb\n","Mounted at /content/gdrive\n"]}],"source":["from image_segment import *"]},{"cell_type":"code","execution_count":5,"metadata":{"colab":{"background_save":true,"base_uri":"https://localhost:8080/","height":135},"executionInfo":{"elapsed":5,"status":"error","timestamp":1682836516847,"user":{"displayName":"Kushi Karkera","userId":"13688612516651987903"},"user_tz":-330},"id":"0Gqq7FPurOGS"},"outputs":[{"name":"stderr","output_type":"stream","text":["ERROR:root:Internal Python error in the inspect module.\n","Below is the traceback from this internal error.\n","\n","ERROR:root:Internal Python error in the inspect module.\n","Below is the traceback from this internal error.\n","\n","ERROR:root:Internal Python error in the inspect module.\n","Below is the traceback from this internal error.\n","\n"]},{"name":"stdout","output_type":"stream","text":["Traceback (most recent call last):\n","  File \"/usr/local/lib/python3.10/dist-packages/IPython/core/interactiveshell.py\", line 3553, in run_code\n","    exec(code_obj, self.user_global_ns, self.user_ns)\n","  File \"\u003cipython-input-6-b3ddfd0e72fa\u003e\", line 36, in \u003ccell line: 33\u003e\n","    print(testing(1,a))\n","NameError: name 'testing' is not defined\n","\n","During handling of the above exception, another exception occurred:\n","\n","Traceback (most recent call last):\n","  File \"/usr/local/lib/python3.10/dist-packages/IPython/core/interactiveshell.py\", line 2099, in showtraceback\n","    stb = value._render_traceback_()\n","AttributeError: 'NameError' object has no attribute '_render_traceback_'\n","\n","During handling of the above exception, another exception occurred:\n","\n","Traceback (most recent call last):\n","  File \"/usr/local/lib/python3.10/dist-packages/IPython/core/ultratb.py\", line 1101, in get_records\n","    return _fixed_getinnerframes(etb, number_of_lines_of_context, tb_offset)\n","  File \"/usr/local/lib/python3.10/dist-packages/IPython/core/ultratb.py\", line 248, in wrapped\n","    return f(*args, **kwargs)\n","  File \"/usr/local/lib/python3.10/dist-packages/IPython/core/ultratb.py\", line 281, in _fixed_getinnerframes\n","    records = fix_frame_records_filenames(inspect.getinnerframes(etb, context))\n","  File \"/usr/lib/python3.10/inspect.py\", line 1662, in getinnerframes\n","    frameinfo = (tb.tb_frame,) + getframeinfo(tb, context)\n","  File \"/usr/lib/python3.10/inspect.py\", line 1620, in getframeinfo\n","    filename = getsourcefile(frame) or getfile(frame)\n","  File \"/usr/lib/python3.10/inspect.py\", line 829, in getsourcefile\n","    module = getmodule(object, filename)\n","  File \"/usr/lib/python3.10/inspect.py\", line 861, in getmodule\n","    file = getabsfile(object, _filename)\n","  File \"/usr/lib/python3.10/inspect.py\", line 845, in getabsfile\n","    return os.path.normcase(os.path.abspath(_filename))\n","  File \"/usr/lib/python3.10/posixpath.py\", line 384, in abspath\n","    cwd = os.getcwd()\n","OSError: [Errno 107] Transport endpoint is not connected\n","Traceback (most recent call last):\n","  File \"/usr/local/lib/python3.10/dist-packages/IPython/core/interactiveshell.py\", line 3553, in run_code\n","    exec(code_obj, self.user_global_ns, self.user_ns)\n","  File \"\u003cipython-input-6-b3ddfd0e72fa\u003e\", line 36, in \u003ccell line: 33\u003e\n","    print(testing(1,a))\n","NameError: name 'testing' is not defined\n","\n","During handling of the above exception, another exception occurred:\n","\n","Traceback (most recent call last):\n","  File \"/usr/local/lib/python3.10/dist-packages/IPython/core/interactiveshell.py\", line 2099, in showtraceback\n","    stb = value._render_traceback_()\n","AttributeError: 'NameError' object has no attribute '_render_traceback_'\n","\n","During handling of the above exception, another exception occurred:\n","\n","Traceback (most recent call last):\n","  File \"/usr/local/lib/python3.10/dist-packages/IPython/core/interactiveshell.py\", line 3473, in run_ast_nodes\n","    if (await self.run_code(code, result,  async_=asy)):\n","  File \"/usr/local/lib/python3.10/dist-packages/IPython/core/interactiveshell.py\", line 3575, in run_code\n","    self.showtraceback(running_compiled_code=True)\n","  File \"/usr/local/lib/python3.10/dist-packages/IPython/core/interactiveshell.py\", line 2101, in showtraceback\n","    stb = self.InteractiveTB.structured_traceback(etype,\n","  File \"/usr/local/lib/python3.10/dist-packages/IPython/core/ultratb.py\", line 1367, in structured_traceback\n","    return FormattedTB.structured_traceback(\n","  File \"/usr/local/lib/python3.10/dist-packages/IPython/core/ultratb.py\", line 1267, in structured_traceback\n","    return VerboseTB.structured_traceback(\n","  File \"/usr/local/lib/python3.10/dist-packages/IPython/core/ultratb.py\", line 1124, in structured_traceback\n","    formatted_exception = self.format_exception_as_a_whole(etype, evalue, etb, number_of_lines_of_context,\n","  File \"/usr/local/lib/python3.10/dist-packages/IPython/core/ultratb.py\", line 1082, in format_exception_as_a_whole\n","    last_unique, recursion_repeat = find_recursion(orig_etype, evalue, records)\n","  File \"/usr/local/lib/python3.10/dist-packages/IPython/core/ultratb.py\", line 382, in find_recursion\n","    return len(records), 0\n","TypeError: object of type 'NoneType' has no len()\n","\n","During handling of the above exception, another exception occurred:\n","\n","Traceback (most recent call last):\n","  File \"/usr/local/lib/python3.10/dist-packages/IPython/core/interactiveshell.py\", line 2099, in showtraceback\n","    stb = value._render_traceback_()\n","AttributeError: 'TypeError' object has no attribute '_render_traceback_'\n","\n","During handling of the above exception, another exception occurred:\n","\n","Traceback (most recent call last):\n","  File \"/usr/local/lib/python3.10/dist-packages/IPython/core/ultratb.py\", line 1101, in get_records\n","    return _fixed_getinnerframes(etb, number_of_lines_of_context, tb_offset)\n","  File \"/usr/local/lib/python3.10/dist-packages/IPython/core/ultratb.py\", line 248, in wrapped\n","    return f(*args, **kwargs)\n","  File \"/usr/local/lib/python3.10/dist-packages/IPython/core/ultratb.py\", line 281, in _fixed_getinnerframes\n","    records = fix_frame_records_filenames(inspect.getinnerframes(etb, context))\n","  File \"/usr/lib/python3.10/inspect.py\", line 1662, in getinnerframes\n","    frameinfo = (tb.tb_frame,) + getframeinfo(tb, context)\n","  File \"/usr/lib/python3.10/inspect.py\", line 1620, in getframeinfo\n","    filename = getsourcefile(frame) or getfile(frame)\n","  File \"/usr/lib/python3.10/inspect.py\", line 829, in getsourcefile\n","    module = getmodule(object, filename)\n","  File \"/usr/lib/python3.10/inspect.py\", line 861, in getmodule\n","    file = getabsfile(object, _filename)\n","  File \"/usr/lib/python3.10/inspect.py\", line 845, in getabsfile\n","    return os.path.normcase(os.path.abspath(_filename))\n","  File \"/usr/lib/python3.10/posixpath.py\", line 384, in abspath\n","    cwd = os.getcwd()\n","OSError: [Errno 107] Transport endpoint is not connected\n","Traceback (most recent call last):\n","  File \"/usr/local/lib/python3.10/dist-packages/IPython/core/interactiveshell.py\", line 3553, in run_code\n","    exec(code_obj, self.user_global_ns, self.user_ns)\n","  File \"\u003cipython-input-6-b3ddfd0e72fa\u003e\", line 36, in \u003ccell line: 33\u003e\n","    print(testing(1,a))\n","NameError: name 'testing' is not defined\n","\n","During handling of the above exception, another exception occurred:\n","\n","Traceback (most recent call last):\n","  File \"/usr/local/lib/python3.10/dist-packages/IPython/core/interactiveshell.py\", line 2099, in showtraceback\n","    stb = value._render_traceback_()\n","AttributeError: 'NameError' object has no attribute '_render_traceback_'\n","\n","During handling of the above exception, another exception occurred:\n","\n","Traceback (most recent call last):\n","  File \"/usr/local/lib/python3.10/dist-packages/IPython/core/interactiveshell.py\", line 3473, in run_ast_nodes\n","    if (await self.run_code(code, result,  async_=asy)):\n","  File \"/usr/local/lib/python3.10/dist-packages/IPython/core/interactiveshell.py\", line 3575, in run_code\n","    self.showtraceback(running_compiled_code=True)\n","  File \"/usr/local/lib/python3.10/dist-packages/IPython/core/interactiveshell.py\", line 2101, in showtraceback\n","    stb = self.InteractiveTB.structured_traceback(etype,\n","  File \"/usr/local/lib/python3.10/dist-packages/IPython/core/ultratb.py\", line 1367, in structured_traceback\n","    return FormattedTB.structured_traceback(\n","  File \"/usr/local/lib/python3.10/dist-packages/IPython/core/ultratb.py\", line 1267, in structured_traceback\n","    return VerboseTB.structured_traceback(\n","  File \"/usr/local/lib/python3.10/dist-packages/IPython/core/ultratb.py\", line 1124, in structured_traceback\n","    formatted_exception = self.format_exception_as_a_whole(etype, evalue, etb, number_of_lines_of_context,\n","  File \"/usr/local/lib/python3.10/dist-packages/IPython/core/ultratb.py\", line 1082, in format_exception_as_a_whole\n","    last_unique, recursion_repeat = find_recursion(orig_etype, evalue, records)\n","  File \"/usr/local/lib/python3.10/dist-packages/IPython/core/ultratb.py\", line 382, in find_recursion\n","    return len(records), 0\n","TypeError: object of type 'NoneType' has no len()\n","\n","During handling of the above exception, another exception occurred:\n","\n","Traceback (most recent call last):\n","  File \"/usr/local/lib/python3.10/dist-packages/IPython/core/interactiveshell.py\", line 2099, in showtraceback\n","    stb = value._render_traceback_()\n","AttributeError: 'TypeError' object has no attribute '_render_traceback_'\n","\n","During handling of the above exception, another exception occurred:\n","\n","Traceback (most recent call last):\n","  File \"/usr/local/lib/python3.10/dist-packages/IPython/core/interactiveshell.py\", line 3030, in _run_cell\n","    return runner(coro)\n","  File \"/usr/local/lib/python3.10/dist-packages/IPython/core/async_helpers.py\", line 78, in _pseudo_sync_runner\n","    coro.send(None)\n","  File \"/usr/local/lib/python3.10/dist-packages/IPython/core/interactiveshell.py\", line 3257, in run_cell_async\n","    has_raised = await self.run_ast_nodes(code_ast.body, cell_name,\n","  File \"/usr/local/lib/python3.10/dist-packages/IPython/core/interactiveshell.py\", line 3492, in run_ast_nodes\n","    self.showtraceback()\n","  File \"/usr/local/lib/python3.10/dist-packages/IPython/core/interactiveshell.py\", line 2101, in showtraceback\n","    stb = self.InteractiveTB.structured_traceback(etype,\n","  File \"/usr/local/lib/python3.10/dist-packages/IPython/core/ultratb.py\", line 1367, in structured_traceback\n","    return FormattedTB.structured_traceback(\n","  File \"/usr/local/lib/python3.10/dist-packages/IPython/core/ultratb.py\", line 1267, in structured_traceback\n","    return VerboseTB.structured_traceback(\n","  File \"/usr/local/lib/python3.10/dist-packages/IPython/core/ultratb.py\", line 1142, in structured_traceback\n","    formatted_exceptions += self.format_exception_as_a_whole(etype, evalue, etb, lines_of_context,\n","  File \"/usr/local/lib/python3.10/dist-packages/IPython/core/ultratb.py\", line 1082, in format_exception_as_a_whole\n","    last_unique, recursion_repeat = find_recursion(orig_etype, evalue, records)\n","  File \"/usr/local/lib/python3.10/dist-packages/IPython/core/ultratb.py\", line 382, in find_recursion\n","    return len(records), 0\n","TypeError: object of type 'NoneType' has no len()\n","\n","During handling of the above exception, another exception occurred:\n","\n","Traceback (most recent call last):\n","  File \"/usr/local/lib/python3.10/dist-packages/IPython/core/interactiveshell.py\", line 2099, in showtraceback\n","    stb = value._render_traceback_()\n","AttributeError: 'TypeError' object has no attribute '_render_traceback_'\n","\n","During handling of the above exception, another exception occurred:\n","\n","Traceback (most recent call last):\n","  File \"/usr/local/lib/python3.10/dist-packages/IPython/core/ultratb.py\", line 1101, in get_records\n","    return _fixed_getinnerframes(etb, number_of_lines_of_context, tb_offset)\n","  File \"/usr/local/lib/python3.10/dist-packages/IPython/core/ultratb.py\", line 248, in wrapped\n","    return f(*args, **kwargs)\n","  File \"/usr/local/lib/python3.10/dist-packages/IPython/core/ultratb.py\", line 281, in _fixed_getinnerframes\n","    records = fix_frame_records_filenames(inspect.getinnerframes(etb, context))\n","  File \"/usr/lib/python3.10/inspect.py\", line 1662, in getinnerframes\n","    frameinfo = (tb.tb_frame,) + getframeinfo(tb, context)\n","  File \"/usr/lib/python3.10/inspect.py\", line 1620, in getframeinfo\n","    filename = getsourcefile(frame) or getfile(frame)\n","  File \"/usr/lib/python3.10/inspect.py\", line 829, in getsourcefile\n","    module = getmodule(object, filename)\n","  File \"/usr/lib/python3.10/inspect.py\", line 861, in getmodule\n","    file = getabsfile(object, _filename)\n","  File \"/usr/lib/python3.10/inspect.py\", line 845, in getabsfile\n","    return os.path.normcase(os.path.abspath(_filename))\n","  File \"/usr/lib/python3.10/posixpath.py\", line 384, in abspath\n","    cwd = os.getcwd()\n","OSError: [Errno 107] Transport endpoint is not connected\n"]}],"source":["import cv2\n","import numpy as np\n","\n","density_dict={1:0.96,2:1.19,3:0.814,4:1,5:0.47,6:0.98}\n","calorie_dict={1:52,2:39,3:47,4:61,5:32,6:30}\n","skin_multiplier=5*2.3\n","\n","def getCalorie(label,volume):\n","  calorie=calorie_dict[int(label)]\n","  density=density_dict[int(label)]\n","  mass=density*volume*1.0\n","  tot_cal=(calorie/100.0)*mass\n","  return mass,tot_cal,calorie\n","\n","def getVolume(label,area,skin_area,pix_to_cm_multiplier,fruit_contour):\n","  area_fruit=(area/skin_area)*skin_multiplier \n","  label=int(label)\n","  volume=100\n","\n","  return volume\n","\n","def calories(result,img):\n","  img_path=img\n","  fruit_areas,final_f,areaod,skin_areas, fruit_contours, pix_cm = getAreaOfFood(img_path)\n","  volume = getVolume(result, fruit_areas, skin_areas, pix_cm, fruit_contours)\n","  mass, cal, cal_100 = getCalorie(result, volume)\n","  fruit_volumes=volume\n","  fruit_calories=cal\n","  fruit_calories_100grams=cal_100\n","  fruit_mass=mass\n","  return fruit_calories\n","\n","if __name__=='__main__':\n","  a=\"\"\n","  a=cv2.imread(a)\n","  print(testing(1,a))"]},{"cell_type":"code","execution_count":null,"metadata":{"colab":{"base_uri":"https://localhost:8080/"},"executionInfo":{"elapsed":9403,"status":"ok","timestamp":1682835481718,"user":{"displayName":"Kushi Karkera","userId":"13688612516651987903"},"user_tz":-330},"id":"yh5lZ1zBMnrP","outputId":"67da47e7-abfb-415d-deb9-83090a79f1d6"},"outputs":[{"name":"stdout","output_type":"stream","text":["Drive already mounted at /content/drive; to attempt to forcibly remount, call drive.mount(\"/content/drive\", force_remount=True).\n"]}],"source":["from google.colab import drive\n","drive.mount('/content/drive')"]}],"metadata":{"colab":{"authorship_tag":"ABX9TyPIWYws6Z7CWhzFT5KTG7P6","mount_file_id":"1WvcHoNOTf3MCdMnFJJ-qDNgPkNzZCkoq","name":"","version":""},"kernelspec":{"display_name":"Python 3","name":"python3"},"language_info":{"name":"python"}},"nbformat":4,"nbformat_minor":0}